<?xml version="1.0" encoding="UTF-8"?>
<!-- Generated by org.testng.reporters.JUnitReportReporter -->
<testsuite hostname="AZU-DESK-019" name="fusepackage.FuseEditPart" tests="11" failures="0" timestamp="19 May 2017 12:21:16 GMT" time="100.969" errors="6">
  <testcase name="attachments" time="56.480" classname="fusepackage.FuseEditPart"/>
  <testcase name="comments" time="0.000" classname="fusepackage.FuseEditPart">
    <error type="java.lang.RuntimeException" message="java.lang.ArrayIndexOutOfBoundsException: 30">
      <![CDATA[java.lang.RuntimeException: java.lang.ArrayIndexOutOfBoundsException: 30
	at org.testng.internal.MethodInvocationHelper.invokeDataProvider(MethodInvocationHelper.java:162)
	at org.testng.internal.Parameters.handleParameters(Parameters.java:430)
	at org.testng.internal.Invoker.handleParameters(Invoker.java:1270)
	at org.testng.internal.Invoker.createParameters(Invoker.java:985)
	at org.testng.internal.Invoker.invokeTestMethods(Invoker.java:1075)
	at org.testng.internal.TestMethodWorker.invokeTestMethods(TestMethodWorker.java:125)
	at org.testng.internal.TestMethodWorker.run(TestMethodWorker.java:108)
	at org.testng.TestRunner.privateRun(TestRunner.java:774)
	at org.testng.TestRunner.run(TestRunner.java:624)
	at org.testng.SuiteRunner.runTest(SuiteRunner.java:359)
	at org.testng.SuiteRunner.runSequentially(SuiteRunner.java:354)
	at org.testng.SuiteRunner.privateRun(SuiteRunner.java:312)
	at org.testng.SuiteRunner.run(SuiteRunner.java:261)
	at org.testng.SuiteRunnerWorker.runSuite(SuiteRunnerWorker.java:52)
	at org.testng.SuiteRunnerWorker.run(SuiteRunnerWorker.java:86)
	at org.testng.TestNG.runSuitesSequentially(TestNG.java:1215)
	at org.testng.TestNG.runSuitesLocally(TestNG.java:1140)
	at org.testng.TestNG.run(TestNG.java:1048)
	at org.testng.remote.AbstractRemoteTestNG.run(AbstractRemoteTestNG.java:132)
	at org.testng.remote.RemoteTestNG.initAndRun(RemoteTestNG.java:236)
	at org.testng.remote.RemoteTestNG.main(RemoteTestNG.java:81)
Caused by: java.lang.ArrayIndexOutOfBoundsException: 30
	at fusepackage.WrapperClass.getcommentsData(WrapperClass.java:1563)
	at fusepackage.FuseEditPart.parameterCredentials5(FuseEditPart.java:249)
	at sun.reflect.NativeMethodAccessorImpl.invoke0(Native Method)
	at sun.reflect.NativeMethodAccessorImpl.invoke(NativeMethodAccessorImpl.java:62)
	at sun.reflect.DelegatingMethodAccessorImpl.invoke(DelegatingMethodAccessorImpl.java:43)
	at java.lang.reflect.Method.invoke(Method.java:498)
	at org.testng.internal.MethodInvocationHelper.invokeMethod(MethodInvocationHelper.java:85)
	at org.testng.internal.MethodInvocationHelper.invokeDataProvider(MethodInvocationHelper.java:136)
	... 20 more
]]>
    </error>
  </testcase> <!-- comments -->
  <testcase name="incrementalrevcheck" time="0.000" classname="fusepackage.FuseEditPart">
    <error type="java.lang.RuntimeException" message="java.lang.ArrayIndexOutOfBoundsException: 3">
      <![CDATA[java.lang.RuntimeException: java.lang.ArrayIndexOutOfBoundsException: 3
	at org.testng.internal.MethodInvocationHelper.invokeDataProvider(MethodInvocationHelper.java:162)
	at org.testng.internal.Parameters.handleParameters(Parameters.java:430)
	at org.testng.internal.Invoker.handleParameters(Invoker.java:1270)
	at org.testng.internal.Invoker.createParameters(Invoker.java:985)
	at org.testng.internal.Invoker.invokeTestMethods(Invoker.java:1075)
	at org.testng.internal.TestMethodWorker.invokeTestMethods(TestMethodWorker.java:125)
	at org.testng.internal.TestMethodWorker.run(TestMethodWorker.java:108)
	at org.testng.TestRunner.privateRun(TestRunner.java:774)
	at org.testng.TestRunner.run(TestRunner.java:624)
	at org.testng.SuiteRunner.runTest(SuiteRunner.java:359)
	at org.testng.SuiteRunner.runSequentially(SuiteRunner.java:354)
	at org.testng.SuiteRunner.privateRun(SuiteRunner.java:312)
	at org.testng.SuiteRunner.run(SuiteRunner.java:261)
	at org.testng.SuiteRunnerWorker.runSuite(SuiteRunnerWorker.java:52)
	at org.testng.SuiteRunnerWorker.run(SuiteRunnerWorker.java:86)
	at org.testng.TestNG.runSuitesSequentially(TestNG.java:1215)
	at org.testng.TestNG.runSuitesLocally(TestNG.java:1140)
	at org.testng.TestNG.run(TestNG.java:1048)
	at org.testng.remote.AbstractRemoteTestNG.run(AbstractRemoteTestNG.java:132)
	at org.testng.remote.RemoteTestNG.initAndRun(RemoteTestNG.java:236)
	at org.testng.remote.RemoteTestNG.main(RemoteTestNG.java:81)
Caused by: java.lang.ArrayIndexOutOfBoundsException: 3
	at fusepackage.WrapperClass.getIncrementalRevisionData(WrapperClass.java:1407)
	at fusepackage.FuseEditPart.parameterCredentials1(FuseEditPart.java:221)
	at sun.reflect.NativeMethodAccessorImpl.invoke0(Native Method)
	at sun.reflect.NativeMethodAccessorImpl.invoke(NativeMethodAccessorImpl.java:62)
	at sun.reflect.DelegatingMethodAccessorImpl.invoke(DelegatingMethodAccessorImpl.java:43)
	at java.lang.reflect.Method.invoke(Method.java:498)
	at org.testng.internal.MethodInvocationHelper.invokeMethod(MethodInvocationHelper.java:85)
	at org.testng.internal.MethodInvocationHelper.invokeDataProvider(MethodInvocationHelper.java:136)
	... 20 more
]]>
    </error>
  </testcase> <!-- incrementalrevcheck -->
  <testcase name="incrementalrev" time="0.000" classname="fusepackage.FuseEditPart">
    <error type="java.lang.RuntimeException" message="java.lang.ArrayIndexOutOfBoundsException: 3">
      <![CDATA[java.lang.RuntimeException: java.lang.ArrayIndexOutOfBoundsException: 3
	at org.testng.internal.MethodInvocationHelper.invokeDataProvider(MethodInvocationHelper.java:162)
	at org.testng.internal.Parameters.handleParameters(Parameters.java:430)
	at org.testng.internal.Invoker.handleParameters(Invoker.java:1270)
	at org.testng.internal.Invoker.createParameters(Invoker.java:985)
	at org.testng.internal.Invoker.invokeTestMethods(Invoker.java:1075)
	at org.testng.internal.TestMethodWorker.invokeTestMethods(TestMethodWorker.java:125)
	at org.testng.internal.TestMethodWorker.run(TestMethodWorker.java:108)
	at org.testng.TestRunner.privateRun(TestRunner.java:774)
	at org.testng.TestRunner.run(TestRunner.java:624)
	at org.testng.SuiteRunner.runTest(SuiteRunner.java:359)
	at org.testng.SuiteRunner.runSequentially(SuiteRunner.java:354)
	at org.testng.SuiteRunner.privateRun(SuiteRunner.java:312)
	at org.testng.SuiteRunner.run(SuiteRunner.java:261)
	at org.testng.SuiteRunnerWorker.runSuite(SuiteRunnerWorker.java:52)
	at org.testng.SuiteRunnerWorker.run(SuiteRunnerWorker.java:86)
	at org.testng.TestNG.runSuitesSequentially(TestNG.java:1215)
	at org.testng.TestNG.runSuitesLocally(TestNG.java:1140)
	at org.testng.TestNG.run(TestNG.java:1048)
	at org.testng.remote.AbstractRemoteTestNG.run(AbstractRemoteTestNG.java:132)
	at org.testng.remote.RemoteTestNG.initAndRun(RemoteTestNG.java:236)
	at org.testng.remote.RemoteTestNG.main(RemoteTestNG.java:81)
Caused by: java.lang.ArrayIndexOutOfBoundsException: 3
	at fusepackage.WrapperClass.getIncrementalRevisionData(WrapperClass.java:1407)
	at fusepackage.FuseEditPart.parameterCredentials1(FuseEditPart.java:221)
	at sun.reflect.NativeMethodAccessorImpl.invoke0(Native Method)
	at sun.reflect.NativeMethodAccessorImpl.invoke(NativeMethodAccessorImpl.java:62)
	at sun.reflect.DelegatingMethodAccessorImpl.invoke(DelegatingMethodAccessorImpl.java:43)
	at java.lang.reflect.Method.invoke(Method.java:498)
	at org.testng.internal.MethodInvocationHelper.invokeMethod(MethodInvocationHelper.java:85)
	at org.testng.internal.MethodInvocationHelper.invokeDataProvider(MethodInvocationHelper.java:136)
	... 20 more
]]>
    </error>
  </testcase> <!-- incrementalrev -->
  <testcase name="billofmaterial" time="0.000" classname="fusepackage.FuseEditPart">
    <error type="java.lang.RuntimeException" message="java.lang.ArrayIndexOutOfBoundsException: 25">
      <![CDATA[java.lang.RuntimeException: java.lang.ArrayIndexOutOfBoundsException: 25
	at org.testng.internal.MethodInvocationHelper.invokeDataProvider(MethodInvocationHelper.java:162)
	at org.testng.internal.Parameters.handleParameters(Parameters.java:430)
	at org.testng.internal.Invoker.handleParameters(Invoker.java:1270)
	at org.testng.internal.Invoker.createParameters(Invoker.java:985)
	at org.testng.internal.Invoker.invokeTestMethods(Invoker.java:1075)
	at org.testng.internal.TestMethodWorker.invokeTestMethods(TestMethodWorker.java:125)
	at org.testng.internal.TestMethodWorker.run(TestMethodWorker.java:108)
	at org.testng.TestRunner.privateRun(TestRunner.java:774)
	at org.testng.TestRunner.run(TestRunner.java:624)
	at org.testng.SuiteRunner.runTest(SuiteRunner.java:359)
	at org.testng.SuiteRunner.runSequentially(SuiteRunner.java:354)
	at org.testng.SuiteRunner.privateRun(SuiteRunner.java:312)
	at org.testng.SuiteRunner.run(SuiteRunner.java:261)
	at org.testng.SuiteRunnerWorker.runSuite(SuiteRunnerWorker.java:52)
	at org.testng.SuiteRunnerWorker.run(SuiteRunnerWorker.java:86)
	at org.testng.TestNG.runSuitesSequentially(TestNG.java:1215)
	at org.testng.TestNG.runSuitesLocally(TestNG.java:1140)
	at org.testng.TestNG.run(TestNG.java:1048)
	at org.testng.remote.AbstractRemoteTestNG.run(AbstractRemoteTestNG.java:132)
	at org.testng.remote.RemoteTestNG.initAndRun(RemoteTestNG.java:236)
	at org.testng.remote.RemoteTestNG.main(RemoteTestNG.java:81)
Caused by: java.lang.ArrayIndexOutOfBoundsException: 25
	at fusepackage.WrapperClass.getbillofmaterialData(WrapperClass.java:1521)
	at fusepackage.FuseEditPart.parameterCredentials4(FuseEditPart.java:242)
	at sun.reflect.NativeMethodAccessorImpl.invoke0(Native Method)
	at sun.reflect.NativeMethodAccessorImpl.invoke(NativeMethodAccessorImpl.java:62)
	at sun.reflect.DelegatingMethodAccessorImpl.invoke(DelegatingMethodAccessorImpl.java:43)
	at java.lang.reflect.Method.invoke(Method.java:498)
	at org.testng.internal.MethodInvocationHelper.invokeMethod(MethodInvocationHelper.java:85)
	at org.testng.internal.MethodInvocationHelper.invokeDataProvider(MethodInvocationHelper.java:136)
	... 20 more
]]>
    </error>
  </testcase> <!-- billofmaterial -->
  <testcase name="editpart" time="9.273" classname="fusepackage.FuseEditPart"/>
  <testcase name="whereused" time="6.230" classname="fusepackage.FuseEditPart"/>
  <testcase name="basicinfo" time="0.000" classname="fusepackage.FuseEditPart">
    <error type="java.lang.RuntimeException" message="java.lang.ArrayIndexOutOfBoundsException: 5">
      <![CDATA[java.lang.RuntimeException: java.lang.ArrayIndexOutOfBoundsException: 5
	at org.testng.internal.MethodInvocationHelper.invokeDataProvider(MethodInvocationHelper.java:162)
	at org.testng.internal.Parameters.handleParameters(Parameters.java:430)
	at org.testng.internal.Invoker.handleParameters(Invoker.java:1270)
	at org.testng.internal.Invoker.createParameters(Invoker.java:985)
	at org.testng.internal.Invoker.invokeTestMethods(Invoker.java:1075)
	at org.testng.internal.TestMethodWorker.invokeTestMethods(TestMethodWorker.java:125)
	at org.testng.internal.TestMethodWorker.run(TestMethodWorker.java:108)
	at org.testng.TestRunner.privateRun(TestRunner.java:774)
	at org.testng.TestRunner.run(TestRunner.java:624)
	at org.testng.SuiteRunner.runTest(SuiteRunner.java:359)
	at org.testng.SuiteRunner.runSequentially(SuiteRunner.java:354)
	at org.testng.SuiteRunner.privateRun(SuiteRunner.java:312)
	at org.testng.SuiteRunner.run(SuiteRunner.java:261)
	at org.testng.SuiteRunnerWorker.runSuite(SuiteRunnerWorker.java:52)
	at org.testng.SuiteRunnerWorker.run(SuiteRunnerWorker.java:86)
	at org.testng.TestNG.runSuitesSequentially(TestNG.java:1215)
	at org.testng.TestNG.runSuitesLocally(TestNG.java:1140)
	at org.testng.TestNG.run(TestNG.java:1048)
	at org.testng.remote.AbstractRemoteTestNG.run(AbstractRemoteTestNG.java:132)
	at org.testng.remote.RemoteTestNG.initAndRun(RemoteTestNG.java:236)
	at org.testng.remote.RemoteTestNG.main(RemoteTestNG.java:81)
Caused by: java.lang.ArrayIndexOutOfBoundsException: 5
	at fusepackage.WrapperClass.getbasicinfoData(WrapperClass.java:1446)
	at fusepackage.FuseEditPart.parameterCredentials2(FuseEditPart.java:228)
	at sun.reflect.NativeMethodAccessorImpl.invoke0(Native Method)
	at sun.reflect.NativeMethodAccessorImpl.invoke(NativeMethodAccessorImpl.java:62)
	at sun.reflect.DelegatingMethodAccessorImpl.invoke(DelegatingMethodAccessorImpl.java:43)
	at java.lang.reflect.Method.invoke(Method.java:498)
	at org.testng.internal.MethodInvocationHelper.invokeMethod(MethodInvocationHelper.java:85)
	at org.testng.internal.MethodInvocationHelper.invokeDataProvider(MethodInvocationHelper.java:136)
	... 20 more
]]>
    </error>
  </testcase> <!-- basicinfo -->
  <testcase name="additionalinfo" time="5.106" classname="fusepackage.FuseEditPart"/>
  <testcase name="changestatus" time="23.880" classname="fusepackage.FuseEditPart"/>
  <testcase name="sourcing" time="0.000" classname="fusepackage.FuseEditPart">
    <error type="java.lang.RuntimeException" message="java.lang.ArrayIndexOutOfBoundsException: 16">
      <![CDATA[java.lang.RuntimeException: java.lang.ArrayIndexOutOfBoundsException: 16
	at org.testng.internal.MethodInvocationHelper.invokeDataProvider(MethodInvocationHelper.java:162)
	at org.testng.internal.Parameters.handleParameters(Parameters.java:430)
	at org.testng.internal.Invoker.handleParameters(Invoker.java:1270)
	at org.testng.internal.Invoker.createParameters(Invoker.java:985)
	at org.testng.internal.Invoker.invokeTestMethods(Invoker.java:1075)
	at org.testng.internal.TestMethodWorker.invokeTestMethods(TestMethodWorker.java:125)
	at org.testng.internal.TestMethodWorker.run(TestMethodWorker.java:108)
	at org.testng.TestRunner.privateRun(TestRunner.java:774)
	at org.testng.TestRunner.run(TestRunner.java:624)
	at org.testng.SuiteRunner.runTest(SuiteRunner.java:359)
	at org.testng.SuiteRunner.runSequentially(SuiteRunner.java:354)
	at org.testng.SuiteRunner.privateRun(SuiteRunner.java:312)
	at org.testng.SuiteRunner.run(SuiteRunner.java:261)
	at org.testng.SuiteRunnerWorker.runSuite(SuiteRunnerWorker.java:52)
	at org.testng.SuiteRunnerWorker.run(SuiteRunnerWorker.java:86)
	at org.testng.TestNG.runSuitesSequentially(TestNG.java:1215)
	at org.testng.TestNG.runSuitesLocally(TestNG.java:1140)
	at org.testng.TestNG.run(TestNG.java:1048)
	at org.testng.remote.AbstractRemoteTestNG.run(AbstractRemoteTestNG.java:132)
	at org.testng.remote.RemoteTestNG.initAndRun(RemoteTestNG.java:236)
	at org.testng.remote.RemoteTestNG.main(RemoteTestNG.java:81)
Caused by: java.lang.ArrayIndexOutOfBoundsException: 16
	at fusepackage.WrapperClass.getsourcingData(WrapperClass.java:1485)
	at fusepackage.FuseEditPart.parameterCredentials3(FuseEditPart.java:235)
	at sun.reflect.NativeMethodAccessorImpl.invoke0(Native Method)
	at sun.reflect.NativeMethodAccessorImpl.invoke(NativeMethodAccessorImpl.java:62)
	at sun.reflect.DelegatingMethodAccessorImpl.invoke(DelegatingMethodAccessorImpl.java:43)
	at java.lang.reflect.Method.invoke(Method.java:498)
	at org.testng.internal.MethodInvocationHelper.invokeMethod(MethodInvocationHelper.java:85)
	at org.testng.internal.MethodInvocationHelper.invokeDataProvider(MethodInvocationHelper.java:136)
	... 20 more
]]>
    </error>
  </testcase> <!-- sourcing -->
</testsuite> <!-- fusepackage.FuseEditPart -->
